Workbook

Sheet GFF
A1: ##gff-version 3
A2: # Sequence Data: seqnum=1;seqlen=4913175;seqhdr=#X._Sof1_WGS Xanthobacter chromosome, complete genome#
A3: # Model Data: version=Prodigal.v2.6.3;run_type=Metagenomic;model=#36|Ralstonia_solanacearum_PSI07|B|66.1|11|1#;gc_cont=66.10;transl_table=11;uses_sd=1 | S3: locus_tag_clean_names | Z3: Info position | AD3: FinaL info
A4: X._Sof1_WGS | B4: Prodigal_v2.6.3 | C4: gene | D4: 1 | E4: 1500 | F4: 272.2 | G4: + | H4: 0 | I4: locus_tag=prodigal_1_1;partial=10;start_type=Edge;rbs_motif=None;rbs_spacer=None;gc_cont=0.684;conf=99.99;score=272.19;cscore=268.97;sscore=3.22;rscore=0.00;uscore=0.00;tscore=3.22; | S4: =MID($I4,11,12) -> prodigal_1_1 | T4: =MID($I4,11,13) -> prodigal_1_1; | U4: =MID($I4,11,14) -> prodigal_1_1;p | V4: =MID($I4,11,15) -> prodigal_1_1;pa | W4: =MID($I4,11,16) -> prodigal_1_1;par | Z4: =MATCH(S4,Description!$A$2:$A$4489,0) -> 1 | AA4: =MATCH(T4,Description!$A$2:$A$4489,0) -> #N/A | AB4: =MATCH(U4,Description!$A$2:$A$4489,0) -> #N/A | AC4: =MATCH(V4,Description!$A$2:$A$4489,0) -> #N/A | AD4: 1
A5: X._Sof1_WGS | B5: Prodigal_v2.6.3 | C5: gene | D5: 1906 | E5: 3030 | F5: 250.3 | G5: + | H5: 0 | I5: locus_tag=prodigal_1_2;partial=00;start_type=ATG;rbs_motif=None;rbs_spacer=None;gc_cont=0.675;conf=99.99;score=249.64;cscore=246.11;sscore=3.53;rscore=-3.31;uscore=2.95;tscore=4.54; | S5: =MID($I5,11,12) -> prodigal_1_2 | T5: =MID($I5,11,13) -> prodigal_1_2; | U5: =MID($I5,11,14) -> prodigal_1_2;p | V5: =MID($I5,11,15) -> prodigal_1_2;pa | W5: =MID($I5,11,16) -> prodigal_1_2;par | Z5: =MATCH(S5,Description!$A$2:$A$4489,0) -> 1113 | AA5: =MATCH(T5,Description!$A$2:$A$4489,0) -> #N/A | AB5: =MATCH(U5,Description!$A$2:$A$4489,0) -> #N/A | AC5: =MATCH(V5,Description!$A$2:$A$4489,0) -> #N/A | AD5: 1113
A6: X._Sof1_WGS | B6: Prodigal_v2.6.3 | C6: gene | D6: 3170 | E6: 4411 | F6: 190.6 | G6: + | H6: 0 | I6: locus_tag=prodigal_1_3;partial=00;start_type=ATG;rbs_motif=None;rbs_spacer=None;gc_cont=0.721;conf=99.99;score=190.65;cscore=190.21;sscore=0.44;rscore=-3.31;uscore=-0.80;tscore=4.54; | S6: =MID($I6,11,12) -> prodigal_1_3 | T6: =MID($I6,11,13) -> prodigal_1_3; | U6: =MID($I6,11,14) -> prodigal_1_3;p | V6: =MID($I6,11,15) -> prodigal_1_3;pa | W6: =MID($I6,11,16) -> prodigal_1_3;par | Z6: =MATCH(S6,Description!$A$2:$A$4489,0) -> 2225 | AA6: =MATCH(T6,Description!$A$2:$A$4489,0) -> #N/A | AB6: =MATCH(U6,Description!$A$2:$A$4489,0) -> #N/A | AC6: =MATCH(V6,Description!$A$2:$A$4489,0) -> #N/A | AD6: 2225
A7: X._Sof1_WGS | B7: Prodigal_v2.6.3 | C7: gene | D7: 4601 | E7: 5272 | F7: 119.5 | G7: + | H7: 0 | I7: locus_tag=prodigal_1_4;partial=00;start_type=ATG;rbs_motif=None;rbs_spacer=None;gc_cont=0.683;conf=100.00;score=118.82;cscore=116.01;sscore=2.81;rscore=-3.31;uscore=2.23;tscore=4.54; | S7: =MID($I7,11,12) -> prodigal_1_4 | T7: =MID($I7,11,13) -> prodigal_1_4; | U7: =MID($I7,11,14) -> prodigal_1_4;p | V7: =MID($I7,11,15) -> prodigal_1_4;pa | W7: =MID($I7,11,16) -> prodigal_1_4;par | Z7: =MATCH(S7,Description!$A$2:$A$4489,0) -> 3337 | AA7: =MATCH(T7,Description!$A$2:$A$4489,0) -> #N/A | AB7: =MATCH(U7,Description!$A$2:$A$4489,0) -> #N/A | AC7: =MATCH(V7,Description!$A$2:$A$4489,0) -> #N/A | AD7: 3337
A8: X._Sof1_WGS | B8: Prodigal_v2.6.3 | C8: gene | D8: 5430 | E8: 6959 | F8: 350.6 | G8: + | H8: 0 | I8: locus_tag=prodigal_1_5;partial=00;start_type=ATG;rbs_motif=None;rbs_spacer=None;gc_cont=0.688;conf=99.99;score=350.64;cscore=346.05;sscore=4.59;rscore=-3.31;uscore=3.36;tscore=4.54; | S8: =MID($I8,11,12) -> prodigal_1_5 | T8: =MID($I8,11,13) -> prodigal_1_5; | U8: =MID($I8,11,14) -> prodigal_1_5;p | V8: =MID($I8,11,15) -> prodigal_1_5;pa | W8: =MID($I8,11,16) -> prodigal_1_5;par | Z8: =MATCH(S8,Description!$A$2:$A$4489,0) -> 3934 | AA8: =MATCH(T8,Description!$A$2:$A$4489,0) -> #N/A | AB8: =MATCH(U8,Description!$A$2:$A$4489,0) -> #N/A | AC8: =MATCH(V8,Description!$A$2:$A$4489,0) -> #N/A | AD8: 3934
A9: X._Sof1_WGS | B9: Prodigal_v2.6.3 | C9: gene | D9: 7202 | E9: 8701 | F9: 354.8 | G9: + | H9: 0 | I9: locus_tag=prodigal_1_6;partial=00;start_type=ATG;rbs_motif=GGAG/GAGG;rbs_spacer=5-10bp;gc_cont=0.651;conf=99.99;score=354.11;cscore=340.10;sscore=14.02;rscore=8.88;uscore=1.24;tscore=4.54; | S9: =MID($I9,11,12) -> prodigal_1_6 | T9: =MID($I9,11,13) -> prodigal_1_6; | U9: =MID($I9,11,14) -> prodigal_1_6;p | V9: =MID($I9,11,15) -> prodigal_1_6;pa | W9: =MID($I9,11,16) -> prodigal_1_6;par | Z9: =MATCH(S9,Description!$A$2:$A$4489,0) -> 4045 | AA9: =MATCH(T9,Description!$A$2:$A$4489,0) -> #N/A | AB9: =MATCH(U9,Description!$A$2:$A$4489,0) -> #N/A | AC9: =MATCH(V9,Description!$A$2:$A$4489,0) -> #N/A | AD9: 4045
A10: X._Sof1_WGS | B10: Prodigal_v2.6.3 | C10: gene | D10: 9183 | E10: 9347 | F10: 18.7 | G10: + | H10: 0 | I10: locus_tag=prodigal_1_7;partial=00;start_type=ATG;rbs_motif=GGA/GAG/AGG;rbs_spacer=5-10bp;gc_cont=0.648;conf=98.44;score=18.03;cscore=17.77;sscore=0.26;rscore=0.47;uscore=-2.50;tscore=2.94; | S10: =MID($I10,11,12) -> prodigal_1_7 | T10: =MID($I10,11,13) -> prodigal_1_7; | U10: =MID($I10,11,14) -> prodigal_1_7;p | V10: =MID($I10,11,15) -> prodigal_1_7;pa | W10: =MID($I10,11,16) -> prodigal_1_7;par | Z10: =MATCH(S10,Description!$A$2:$A$4489,0) -> 4156 | AA10: =MATCH(T10,Description!$A$2:$A$4489,0) -> #N/A | AB10: =MATCH(U10,Description!$A$2:$A$4489,0) -> #N/A | AC10: =MATCH(V10,Description!$A$2:$A$4489,0) -> #N/A | AD10: 4156
A11: X._Sof1_WGS | B11: Prodigal_v2.6.3 | C11: gene | D11: 9356 | E11: 9832 | F11: 104 | G11: + | H11: 0 | I11: locus_tag=prodigal_1_8;partial=00;start_type=ATG;rbs_motif=GGAG/GAGG;rbs_spacer=5-10bp;gc_cont=0.683;conf=100.00;score=105.22;cscore=91.36;sscore=13.86;rscore=8.88;uscore=-0.75;tscore=4.54; | S11: =MID($I11,11,12) -> prodigal_1_8 | T11: =MID($I11,11,13) -> prodigal_1_8; | U11: =MID($I11,11,14) -> prodigal_1_8;p | V11: =MID($I11,11,15) -> prodigal_1_8;pa | W11: =MID($I11,11,16) -> prodigal_1_8;par | Z11: =MATCH(S11,Description!$A$2:$A$4489,0) -> 4267 | AA11: =MATCH(T11,Description!$A$2:$A$4489,0) -> #N/A | AB11: =MATCH(U11,Description!$A$2:$A$4489,0) -> #N/A | AC11: =MATCH(V11,Description!$A$2:$A$4489,0) -> #N/A | AD11: 4267
A12: X._Sof1_WGS | B12: Prodigal_v2.6.3 | C12: gene | D12: 9905 | E12: 11275 | F12: 291.6 | G12: + | H12: 0 | I12: locus_tag=prodigal_1_9;partial=00;start_type=ATG;rbs_motif=AGGAG;rbs_spacer=5-10bp;gc_cont=0.729;conf=99.99;score=291.55;cscore=268.37;sscore=23.18;rscore=15.89;uscore=2.74;tscore=4.54; | S12: =MID($I12,11,12) -> prodigal_1_9 | T12: =MID($I12,11,13) -> prodigal_1_9; | U12: =MID($I12,11,14) -> prodigal_1_9;p | V12: =MID($I12,11,15) -> prodigal_1_9;pa | W12: =MID($I12,11,16) -> prodigal_1_9;par | Z12: =MATCH(S12,Description!$A$2:$A$4489,0) -> 4378 | AA12: =MATCH(T12,Description!$A$2:$A$4489,0) -> #N/A | AB12: =MATCH(U12,Description!$A$2:$A$4489,0) -> #N/A | AC12: =MATCH(V12,Description!$A$2:$A$4489,0) -> #N/A | AD12: 4378
A13: X._Sof1_WGS | B13: Prodigal_v2.6.3 | C13: gene | D13: 11272 | E13: 12129 | F13: 105.1 | G13: + | H13: 0 | I13: locus_tag=prodigal_1_10;partial=00;start_type=GTG;rbs_motif=None;rbs_spacer=None;gc_cont=0.742;conf=100.00;score=109.73;cscore=115.14;sscore=-5.41;rscore=-3.31;uscore=1.43;tscore=-8.13; | S13: =MID($I13,11,12) -> prodigal_1_1 | T13: =MID($I13,11,13) -> prodigal_1_10 | U13: =MID($I13,11,14) -> prodigal_1_10; | V13: =MID($I13,11,15) -> prodigal_1_10;p | W13: =MID($I13,11,16) -> prodigal_1_10;pa | Z13: =MATCH(S13,Description!$A$2:$A$4489,0) -> 1 | AA13: =MATCH(T13,Description!$A$2:$A$4489,0) -> 2 | AB13: =MATCH(U13,Description!$A$2:$A$4489,0) -> #N/A | AC13: =MATCH(V13,Description!$A$2:$A$4489,0) -> #N/A | AD13: 1
A14: X._Sof1_WGS | B14: Prodigal_v2.6.3 | C14: gene | D14: 12157 | E14: 13788 | F14: 277.8 | G14: - | H14: 0 | I14: locus_tag=prodigal_1_11;partial=00;start_type=ATG;rbs_motif=AGGAG/GGAGG;rbs_spacer=11-12bp;gc_cont=0.691;conf=99.99;score=277.15;cscore=273.13;sscore=4.02;rscore=0.66;uscore=-0.53;tscore=4.54; | S14: =MID($I14,11,12) -> prodigal_1_1 | T14: =MID($I14,11,13) -> prodigal_1_11 | U14: =MID($I14,11,14) -> prodigal_1_11; | V14: =MID($I14,11,15) -> prodigal_1_11;p | W14: =MID($I14,11,16) -> prodigal_1_11;pa | Z14: =MATCH(S14,Description!$A$2:$A$4489,0) -> 1 | AA14: =MATCH(T14,Description!$A$2:$A$4489,0) -> 113 | AB14: =MATCH(U14,Description!$A$2:$A$4489,0) -> #N/A | AC14: =MATCH(V14,Description!$A$2:$A$4489,0) -> #N/A | AD14: 1
A15: X._Sof1_WGS | B15: Prodigal_v2.6.3 | C15: gene | D15: 13906 | E15: 14613 | F15: 127.4 | G15: + | H15: 0 | I15: locus_tag=prodigal_1_12;partial=00;start_type=ATG;rbs_motif=AGGAG;rbs_spacer=5-10bp;gc_cont=0.722;conf=100.00;score=127.44;cscore=104.02;sscore=23.42;rscore=15.89;uscore=2.98;tscore=4.54; | S15: =MID($I15,11,12) -> prodigal_1_1 | T15: =MID($I15,11,13) -> prodigal_1_12 | U15: =MID($I15,11,14) -> prodigal_1_12; | V15: =MID($I15,11,15) -> prodigal_1_12;p | W15: =MID($I15,11,16) -> prodigal_1_12;pa | Z15: =MATCH(S15,Description!$A$2:$A$4489,0) -> 1 | AA15: =MATCH(T15,Description!$A$2:$A$4489,0) -> 224 | AB15: =MATCH(U15,Description!$A$2:$A$4489,0) -> #N/A | AC15: =MATCH(V15,Description!$A$2:$A$4489,0) -> #N/A | AD15: 1
... A4488: X._Sof1_WGS | B4488: Prodigal_v2.6.3 | C4488: gene | D4488: 4911889 | E4488: 4912155 | F4488: 44.2 | G4488: + | H4488: 0 | I4488: locus_tag=prodigal_1_4485;partial=00;start_type=ATG;rbs_motif=AGGA;rbs_spacer=5-10bp;gc_cont=0.685;conf=100.00;score=44.19;cscore=31.58;sscore=12.60;rscore=7.30;uscore=0.76;tscore=4.54; | S4488: =MID($I4488,11,12) -> prodigal_1_4 | T4488: =MID($I4488,11,13) -> prodigal_1_44 | U4488: =MID($I4488,11,14) -> prodigal_1_448 | V4488: =MID($I4488,11,15) -> prodigal_1_4485 | W4488: =MID($I4488,11,16) -> prodigal_1_4485; | Z4488: =MATCH(S4488,Description!$A$2:$A$4489,0) -> 3337 | AA4488: =MATCH(T4488,Description!$A$2:$A$4489,0) -> 3782 | AB4488: =MATCH(U4488,Description!$A$2:$A$4489,0) -> 3871 | AC4488: =MATCH(V4488,Description!$A$2:$A$4489,0) -> 3877 | AD4488: 3337

Sheet Merged
A1: ##gff-version 3
A2: # Sequence Data: seqnum=1;seqlen=4913175;seqhdr=#X._Sof1_WGS Xanthobacter chromosome, complete genome# | AJ2: ;
A3: # Model Data: version=Prodigal.v2.6.3;run_type=Metagenomic;model=#36|Ralstonia_solanacearum_PSI07|B|66.1|11|1#;gc_cont=66.10;transl_table=11;uses_sd=1 | S3: locus_tag_clean_names | Z3: Info position | AD3: FinaL info | AE3: locus_tag | AF3: shortName | AG3: longName | AH3: product | AI3: gene | AJ3: custom_tag
A4: X._Sof1_WGS | B4: Prodigal_v2.6.3 | C4: gene | D4: 1 | E4: 1500 | F4: 272.2 | G4: + | H4: 0 | I4: locus_tag=prodigal_1_1;partial=10;start_type=Edge;rbs_motif=None;rbs_spacer=None;gc_cont=0.684;conf=99.99;score=272.19;cscore=268.97;sscore=3.22;rscore=0.00;uscore=0.00;tscore=3.22; | S4: =MID($I4,11,12) -> prodigal_1_1 | T4: =MID($I4,11,13) -> prodigal_1_1; | U4: =MID($I4,11,14) -> prodigal_1_1;p | V4: =MID($I4,11,15) -> prodigal_1_1;pa | W4: =MID($I4,11,16) -> prodigal_1_1;par | Z4: =MATCH(S4,Description!$A$2:$A$4489,0) -> 1 | AA4: =MATCH(T4,Description!$A$2:$A$4489,0) -> #N/A | AB4: =MATCH(U4,Description!$A$2:$A$4489,0) -> #N/A | AC4: =MATCH(V4,Description!$A$2:$A$4489,0) -> #N/A | AD4: 1 | AE4: {=INDEX(Description!A$2:A$4489,Merged!$AD4)} -> prodigal_1_1 | AF4: {=INDEX(Description!B$2:B$4489,Merged!$AD4)} -> A7IB67 | AG4: {=INDEX(Description!C$2:C$4489,Merged!$AD4)} -> DNAA_XANP2 | AH4: {=INDEX(Description!D$2:D$4489,Merged!$AD4)} -> Chromosomal_replication_initiator_protein_DnaA | AI4: {=INDEX(Description!E$2:E$4489,Merged!$AD4)} -> dnaA | AJ4: =I4&$AJ$2&AF4&$AJ$2&AG4&$AJ$2&AH4&$AJ$2&AI4 -> locus_tag=prodigal_1_1;partial=10;start_type=Edge;rbs_motif=None;rbs_spacer=None;gc_cont=0.684;conf=99.99;score=272.19;cscore=268.97;sscore=3.22;rscore=0.00;uscore=0.00;tscore=3.22;;A7IB67;DNAA_XANP2;Chromosomal_replication_initiator_protein_DnaA;dnaA
A5: X._Sof1_WGS | B5: Prodigal_v2.6.3 | C5: gene | D5: 1906 | E5: 3030 | F5: 250.3 | G5: + | H5: 0 | I5: locus_tag=prodigal_1_2;partial=00;start_type=ATG;rbs_motif=None;rbs_spacer=None;gc_cont=0.675;conf=99.99;score=249.64;cscore=246.11;sscore=3.53;rscore=-3.31;uscore=2.95;tscore=4.54; | S5: =MID($I5,11,12) -> prodigal_1_2 | T5: =MID($I5,11,13) -> prodigal_1_2; | U5: =MID($I5,11,14) -> prodigal_1_2;p | V5: =MID($I5,11,15) -> prodigal_1_2;pa | W5: =MID($I5,11,16) -> prodigal_1_2;par | Z5: =MATCH(S5,Description!$A$2:$A$4489,0) -> 1113 | AA5: =MATCH(T5,Description!$A$2:$A$4489,0) -> #N/A | AB5: =MATCH(U5,Description!$A$2:$A$4489,0) -> #N/A | AC5: =MATCH(V5,Description!$A$2:$A$4489,0) -> #N/A | AD5: 1113 | AE5: {=INDEX(Description!A$2:A$4489,Merged!$AD5)} -> prodigal_1_2 | AF5: {=INDEX(Description!B$2:B$4489,Merged!$AD5)} -> B8GXP6 | AG5: {=INDEX(Description!C$2:C$4489,Merged!$AD5)} -> DPO3B_CAUVN | AH5: {=INDEX(Description!D$2:D$4489,Merged!$AD5)} -> Beta_sliding_clamp | AI5: {=INDEX(Description!E$2:E$4489,Merged!$AD5)} -> dnaN | AJ5: =I5&$AJ$2&AF5&$AJ$2&AG5&$AJ$2&AH5&$AJ$2&AI5 -> locus_tag=prodigal_1_2;partial=00;start_type=ATG;rbs_motif=None;rbs_spacer=None;gc_cont=0.675;conf=99.99;score=249.64;cscore=246.11;sscore=3.53;rscore=-3.31;uscore=2.95;tscore=4.54;;B8GXP6;DPO3B_CAUVN;Beta_sliding_clamp;dnaN
A6: X._Sof1_WGS | B6: Prodigal_v2.6.3 | C6: gene | D6: 3170 | E6: 4411 | F6: 190.6 | G6: + | H6: 0 | I6: locus_tag=prodigal_1_3;partial=00;start_type=ATG;rbs_motif=None;rbs_spacer=None;gc_cont=0.721;conf=99.99;score=190.65;cscore=190.21;sscore=0.44;rscore=-3.31;uscore=-0.80;tscore=4.54; | S6: =MID($I6,11,12) -> prodigal_1_3 | T6: =MID($I6,11,13) -> prodigal_1_3; | U6: =MID($I6,11,14) -> prodigal_1_3;p | V6: =MID($I6,11,15) -> prodigal_1_3;pa | W6: =MID($I6,11,16) -> prodigal_1_3;par | Z6: =MATCH(S6,Description!$A$2:$A$4489,0) -> 2225 | AA6: =MATCH(T6,Description!$A$2:$A$4489,0) -> #N/A | AB6: =MATCH(U6,Description!$A$2:$A$4489,0) -> #N/A | AC6: =MATCH(V6,Description!$A$2:$A$4489,0) -> #N/A | AD6: 2225 | AE6: {=INDEX(Description!A$2:A$4489,Merged!$AD6)} -> prodigal_1_3 | AF6: {=INDEX(Description!B$2:B$4489,Merged!$AD6)} -> Q98BH1 | AG6: {=INDEX(Description!C$2:C$4489,Merged!$AD6)} -> RECF_RHILO | AH6: {=INDEX(Description!D$2:D$4489,Merged!$AD6)} -> DNA_replication_and_repair_protein_RecF | AI6: {=INDEX(Description!E$2:E$4489,Merged!$AD6)} -> recF | AJ6: =I6&$AJ$2&AF6&$AJ$2&AG6&$AJ$2&AH6&$AJ$2&AI6 -> locus_tag=prodigal_1_3;partial=00;start_type=ATG;rbs_motif=None;rbs_spacer=None;gc_cont=0.721;conf=99.99;score=190.65;cscore=190.21;sscore=0.44;rscore=-3.31;uscore=-0.80;tscore=4.54;;Q98BH1;RECF_RHILO;DNA_replication_and_repair_protein_RecF;recF
A7: X._Sof1_WGS | B7: Prodigal_v2.6.3 | C7: gene | D7: 4601 | E7: 5272 | F7: 119.5 | G7: + | H7: 0 | I7: locus_tag=prodigal_1_4;partial=00;start_type=ATG;rbs_motif=None;rbs_spacer=None;gc_cont=0.683;conf=100.00;score=118.82;cscore=116.01;sscore=2.81;rscore=-3.31;uscore=2.23;tscore=4.54; | S7: =MID($I7,11,12) -> prodigal_1_4 | T7: =MID($I7,11,13) -> prodigal_1_4; | U7: =MID($I7,11,14) -> prodigal_1_4;p | V7: =MID($I7,11,15) -> prodigal_1_4;pa | W7: =MID($I7,11,16) -> prodigal_1_4;par | Z7: =MATCH(S7,Description!$A$2:$A$4489,0) -> 3337 | AA7: =MATCH(T7,Description!$A$2:$A$4489,0) -> #N/A | AB7: =MATCH(U7,Description!$A$2:$A$4489,0) -> #N/A | AC7: =MATCH(V7,Description!$A$2:$A$4489,0) -> #N/A | AD7: 3337 | AE7: {=INDEX(Description!A$2:A$4489,Merged!$AD7)} -> prodigal_1_4 | AF7: {=INDEX(Description!B$2:B$4489,Merged!$AD7)} -> P75954 | AG7: {=INDEX(Description!C$2:C$4489,Merged!$AD7)} -> YCFS_ECOLI | AH7: {=INDEX(Description!D$2:D$4489,Merged!$AD7)} -> Probable_L,D-transpeptidase_YcfS | AI7: {=INDEX(Description!E$2:E$4489,Merged!$AD7)} -> ycfS | AJ7: =I7&$AJ$2&AF7&$AJ$2&AG7&$AJ$2&AH7&$AJ$2&AI7 -> locus_tag=prodigal_1_4;partial=00;start_type=ATG;rbs_motif=None;rbs_spacer=None;gc_cont=0.683;conf=100.00;score=118.82;cscore=116.01;sscore=2.81;rscore=-3.31;uscore=2.23;tscore=4.54;;P75954;YCFS_ECOLI;Probable_L,D-transpeptidase_YcfS;ycfS
A8: X._Sof1_WGS | B8: Prodigal_v2.6.3 | C8: gene | D8: 5430 | E8: 6959 | F8: 350.6 | G8: + | H8: 0 | I8: locus_tag=prodigal_1_5;partial=00;start_type=ATG;rbs_motif=None;rbs_spacer=None;gc_cont=0.688;conf=99.99;score=350.64;cscore=346.05;sscore=4.59;rscore=-3.31;uscore=3.36;tscore=4.54; | S8: =MID($I8,11,12) -> prodigal_1_5 | T8: =MID($I8,11,13) -> prodigal_1_5; | U8: =MID($I8,11,14) -> prodigal_1_5;p | V8: =MID($I8,11,15) -> prodigal_1_5;pa | W8: =MID($I8,11,16) -> prodigal_1_5;par | Z8: =MATCH(S8,Description!$A$2:$A$4489,0) -> 3934 | AA8: =MATCH(T8,Description!$A$2:$A$4489,0) -> #N/A | AB8: =MATCH(U8,Description!$A$2:$A$4489,0) -> #N/A | AC8: =MATCH(V8,Description!$A$2:$A$4489,0) -> #N/A | AD8: 3934 | AE8: {=INDEX(Description!A$2:A$4489,Merged!$AD8)} -> prodigal_1_5 | AF8: {=INDEX(Description!B$2:B$4489,Merged!$AD8)} -> A9MDU4 | AG8: {=INDEX(Description!C$2:C$4489,Merged!$AD8)} -> SYH_BRUC2 | AH8: {=INDEX(Description!D$2:D$4489,Merged!$AD8)} -> Histidine--tRNA_ligase | AI8: {=INDEX(Description!E$2:E$4489,Merged!$AD8)} -> hisS | AJ8: =I8&$AJ$2&AF8&$AJ$2&AG8&$AJ$2&AH8&$AJ$2&AI8 -> locus_tag=prodigal_1_5;partial=00;start_type=ATG;rbs_motif=None;rbs_spacer=None;gc_cont=0.688;conf=99.99;score=350.64;cscore=346.05;sscore=4.59;rscore=-3.31;uscore=3.36;tscore=4.54;;A9MDU4;SYH_BRUC2;Histidine--tRNA_ligase;hisS
A9: X._Sof1_WGS | B9: Prodigal_v2.6.3 | C9: gene | D9: 7202 | E9: 8701 | F9: 354.8 | G9: + | H9: 0 | I9: locus_tag=prodigal_1_6;partial=00;start_type=ATG;rbs_motif=GGAG/GAGG;rbs_spacer=5-10bp;gc_cont=0.651;conf=99.99;score=354.11;cscore=340.10;sscore=14.02;rscore=8.88;uscore=1.24;tscore=4.54; | S9: =MID($I9,11,12) -> prodigal_1_6 | T9: =MID($I9,11,13) -> prodigal_1_6; | U9: =MID($I9,11,14) -> prodigal_1_6;p | V9: =MID($I9,11,15) -> prodigal_1_6;pa | W9: =MID($I9,11,16) -> prodigal_1_6;par | Z9: =MATCH(S9,Description!$A$2:$A$4489,0) -> 4045 | AA9: =MATCH(T9,Description!$A$2:$A$4489,0) -> #N/A | AB9: =MATCH(U9,Description!$A$2:$A$4489,0) -> #N/A | AC9: =MATCH(V9,Description!$A$2:$A$4489,0) -> #N/A | AD9: 4045 | AE9: {=INDEX(Description!A$2:A$4489,Merged!$AD9)} -> prodigal_1_6 | AF9: {=INDEX(Description!B$2:B$4489,Merged!$AD9)} -> Q8U2H4 | AG9: {=INDEX(Description!C$2:C$4489,Merged!$AD9)} -> GLMM_PYRFU | AH9: {=INDEX(Description!D$2:D$4489,Merged!$AD9)} -> Probable_phosphoglucosamine_mutase | AI9: {=INDEX(Description!E$2:E$4489,Merged!$AD9)} -> glmM | AJ9: =I9&$AJ$2&AF9&$AJ$2&AG9&$AJ$2&AH9&$AJ$2&AI9 -> locus_tag=prodigal_1_6;partial=00;start_type=ATG;rbs_motif=GGAG/GAGG;rbs_spacer=5-10bp;gc_cont=0.651;conf=99.99;score=354.11;cscore=340.10;sscore=14.02;rscore=8.88;uscore=1.24;tscore=4.54;;Q8U2H4;GLMM_PYRFU;Probable_phosphoglucosamine_mutase;glmM
A10: X._Sof1_WGS | B10: Prodigal_v2.6.3 | C10: gene | D10: 9183 | E10: 9347 | F10: 18.7 | G10: + | H10: 0 | I10: locus_tag=prodigal_1_7;partial=00;start_type=ATG;rbs_motif=GGA/GAG/AGG;rbs_spacer=5-10bp;gc_cont=0.648;conf=98.44;score=18.03;cscore=17.77;sscore=0.26;rscore=0.47;uscore=-2.50;tscore=2.94; | S10: =MID($I10,11,12) -> prodigal_1_7 | T10: =MID($I10,11,13) -> prodigal_1_7; | U10: =MID($I10,11,14) -> prodigal_1_7;p | V10: =MID($I10,11,15) -> prodigal_1_7;pa | W10: =MID($I10,11,16) -> prodigal_1_7;par | Z10: =MATCH(S10,Description!$A$2:$A$4489,0) -> 4156 | AA10: =MATCH(T10,Description!$A$2:$A$4489,0) -> #N/A | AB10: =MATCH(U10,Description!$A$2:$A$4489,0) -> #N/A | AC10: =MATCH(V10,Description!$A$2:$A$4489,0) -> #N/A | AD10: 4156 | AE10: {=INDEX(Description!A$2:A$4489,Merged!$AD10)} -> prodigal_1_7 | AF10: {=INDEX(Description!B$2:B$4489,Merged!$AD10)} -> * | AG10: {=INDEX(Description!C$2:C$4489,Merged!$AD10)} -> 0 | AH10: {=INDEX(Description!D$2:D$4489,Merged!$AD10)} -> 0 | AI10: {=INDEX(Description!E$2:E$4489,Merged!$AD10)} -> 0 | AJ10: =I10&$AJ$2&AF10&$AJ$2&AG10&$AJ$2&AH10&$AJ$2&AI10 -> locus_tag=prodigal_1_7;partial=00;start_type=ATG;rbs_motif=GGA/GAG/AGG;rbs_spacer=5-10bp;gc_cont=0.648;conf=98.44;score=18.03;cscore=17.77;sscore=0.26;rscore=0.47;uscore=-2.50;tscore=2.94;;*;0;0;0
A11: X._Sof1_WGS | B11: Prodigal_v2.6.3 | C11: gene | D11: 9356 | E11: 9832 | F11: 104 | G11: + | H11: 0 | I11: locus_tag=prodigal_1_8;partial=00;start_type=ATG;rbs_motif=GGAG/GAGG;rbs_spacer=5-10bp;gc_cont=0.683;conf=100.00;score=105.22;cscore=91.36;sscore=13.86;rscore=8.88;uscore=-0.75;tscore=4.54; | S11: =MID($I11,11,12) -> prodigal_1_8 | T11: =MID($I11,11,13) -> prodigal_1_8; | U11: =MID($I11,11,14) -> prodigal_1_8;p | V11: =MID($I11,11,15) -> prodigal_1_8;pa | W11: =MID($I11,11,16) -> prodigal_1_8;par | Z11: =MATCH(S11,Description!$A$2:$A$4489,0) -> 4267 | AA11: =MATCH(T11,Description!$A$2:$A$4489,0) -> #N/A | AB11: =MATCH(U11,Description!$A$2:$A$4489,0) -> #N/A | AC11: =MATCH(V11,Description!$A$2:$A$4489,0) -> #N/A | AD11: 4267 | AE11: {=INDEX(Description!A$2:A$4489,Merged!$AD11)} -> prodigal_1_8 | AF11: {=INDEX(Description!B$2:B$4489,Merged!$AD11)} -> * | AG11: {=INDEX(Description!C$2:C$4489,Merged!$AD11)} -> 0 | AH11: {=INDEX(Description!D$2:D$4489,Merged!$AD11)} -> 0 | AI11: {=INDEX(Description!E$2:E$4489,Merged!$AD11)} -> 0 | AJ11: =I11&$AJ$2&AF11&$AJ$2&AG11&$AJ$2&AH11&$AJ$2&AI11 -> locus_tag=prodigal_1_8;partial=00;start_type=ATG;rbs_motif=GGAG/GAGG;rbs_spacer=5-10bp;gc_cont=0.683;conf=100.00;score=105.22;cscore=91.36;sscore=13.86;rscore=8.88;uscore=-0.75;tscore=4.54;;*;0;0;0
A12: X._Sof1_WGS | B12: Prodigal_v2.6.3 | C12: gene | D12: 9905 | E12: 11275 | F12: 291.6 | G12: + | H12: 0 | I12: locus_tag=prodigal_1_9;partial=00;start_type=ATG;rbs_motif=AGGAG;rbs_spacer=5-10bp;gc_cont=0.729;conf=99.99;score=291.55;cscore=268.37;sscore=23.18;rscore=15.89;uscore=2.74;tscore=4.54; | S12: =MID($I12,11,12) -> prodigal_1_9 | T12: =MID($I12,11,13) -> prodigal_1_9; | U12: =MID($I12,11,14) -> prodigal_1_9;p | V12: =MID($I12,11,15) -> prodigal_1_9;pa | W12: =MID($I12,11,16) -> prodigal_1_9;par | Z12: =MATCH(S12,Description!$A$2:$A$4489,0) -> 4378 | AA12: =MATCH(T12,Description!$A$2:$A$4489,0) -> #N/A | AB12: =MATCH(U12,Description!$A$2:$A$4489,0) -> #N/A | AC12: =MATCH(V12,Description!$A$2:$A$4489,0) -> #N/A | AD12: 4378 | AE12: {=INDEX(Description!A$2:A$4489,Merged!$AD12)} -> prodigal_1_9 | AF12: {=INDEX(Description!B$2:B$4489,Merged!$AD12)} -> A7NG41 | AG12: {=INDEX(Description!C$2:C$4489,Merged!$AD12)} -> AMPA_ROSCS | AH12: {=INDEX(Description!D$2:D$4489,Merged!$AD12)} -> Probable_cytosol_aminopeptidase | AI12: {=INDEX(Description!E$2:E$4489,Merged!$AD12)} -> pepA | AJ12: =I12&$AJ$2&AF12&$AJ$2&AG12&$AJ$2&AH12&$AJ$2&AI12 -> locus_tag=prodigal_1_9;partial=00;start_type=ATG;rbs_motif=AGGAG;rbs_spacer=5-10bp;gc_cont=0.729;conf=99.99;score=291.55;cscore=268.37;sscore=23.18;rscore=15.89;uscore=2.74;tscore=4.54;;A7NG41;AMPA_ROSCS;Probable_cytosol_aminopeptidase;pepA
A13: X._Sof1_WGS | B13: Prodigal_v2.6.3 | C13: gene | D13: 11272 | E13: 12129 | F13: 105.1 | G13: + | H13: 0 | I13: locus_tag=prodigal_1_10;partial=00;start_type=GTG;rbs_motif=None;rbs_spacer=None;gc_cont=0.742;conf=100.00;score=109.73;cscore=115.14;sscore=-5.41;rscore=-3.31;uscore=1.43;tscore=-8.13; | S13: =MID($I13,11,12) -> prodigal_1_1 | T13: =MID($I13,11,13) -> prodigal_1_10 | U13: =MID($I13,11,14) -> prodigal_1_10; | V13: =MID($I13,11,15) -> prodigal_1_10;p | W13: =MID($I13,11,16) -> prodigal_1_10;pa | Z13: =MATCH(S13,Description!$A$2:$A$4489,0) -> 1 | AA13: =MATCH(T13,Description!$A$2:$A$4489,0) -> 2 | AB13: =MATCH(U13,Description!$A$2:$A$4489,0) -> #N/A | AC13: =MATCH(V13,Description!$A$2:$A$4489,0) -> #N/A | AD13: 2 | AE13: {=INDEX(Description!A$2:A$4489,Merged!$AD13)} -> prodigal_1_10 | AF13: {=INDEX(Description!B$2:B$4489,Merged!$AD13)} -> O35010 | AG13: {=INDEX(Description!C$2:C$4489,Merged!$AD13)} -> YKFC_BACSU | AH13: {=INDEX(Description!D$2:D$4489,Merged!$AD13)} -> Gamma-D-glutamyl-L-lysine_dipeptidyl-peptidase | AI13: {=INDEX(Description!E$2:E$4489,Merged!$AD13)} -> ykfC | AJ13: =I13&$AJ$2&AF13&$AJ$2&AG13&$AJ$2&AH13&$AJ$2&AI13 -> locus_tag=prodigal_1_10;partial=00;start_type=GTG;rbs_motif=None;rbs_spacer=None;gc_cont=0.742;conf=100.00;score=109.73;cscore=115.14;sscore=-5.41;rscore=-3.31;uscore=1.43;tscore=-8.13;;O35010;YKFC_BACSU;Gamma-D-glutamyl-L-lysine_dipeptidyl-peptidase;ykfC
A14: X._Sof1_WGS | B14: Prodigal_v2.6.3 | C14: gene | D14: 12157 | E14: 13788 | F14: 277.8 | G14: - | H14: 0 | I14: locus_tag=prodigal_1_11;partial=00;start_type=ATG;rbs_motif=AGGAG/GGAGG;rbs_spacer=11-12bp;gc_cont=0.691;conf=99.99;score=277.15;cscore=273.13;sscore=4.02;rscore=0.66;uscore=-0.53;tscore=4.54; | S14: =MID($I14,11,12) -> prodigal_1_1 | T14: =MID($I14,11,13) -> prodigal_1_11 | U14: =MID($I14,11,14) -> prodigal_1_11; | V14: =MID($I14,11,15) -> prodigal_1_11;p | W14: =MID($I14,11,16) -> prodigal_1_11;pa | Z14: =MATCH(S14,Description!$A$2:$A$4489,0) -> 1 | AA14: =MATCH(T14,Description!$A$2:$A$4489,0) -> 113 | AB14: =MATCH(U14,Description!$A$2:$A$4489,0) -> #N/A | AC14: =MATCH(V14,Description!$A$2:$A$4489,0) -> #N/A | AD14: 113 | AE14: {=INDEX(Description!A$2:A$4489,Merged!$AD14)} -> prodigal_1_11 | AF14: {=INDEX(Description!B$2:B$4489,Merged!$AD14)} -> Q55434 | AG14: {=INDEX(Description!C$2:C$4489,Merged!$AD14)} -> PHY2_SYNY3 | AH14: {=INDEX(Description!D$2:D$4489,Merged!$AD14)} -> Phytochrome-like_protein_cph2 | AI14: {=INDEX(Description!E$2:E$4489,Merged!$AD14)} -> cph2 | AJ14: =I14&$AJ$2&AF14&$AJ$2&AG14&$AJ$2&AH14&$AJ$2&AI14 -> locus_tag=prodigal_1_11;partial=00;start_type=ATG;rbs_motif=AGGAG/GGAGG;rbs_spacer=11-12bp;gc_cont=0.691;conf=99.99;score=277.15;cscore=273.13;sscore=4.02;rscore=0.66;uscore=-0.53;tscore=4.54;;Q55434;PHY2_SYNY3;Phytochrome-like_protein_cph2;cph2
A15: X._Sof1_WGS | B15: Prodigal_v2.6.3 | C15: gene | D15: 13906 | E15: 14613 | F15: 127.4 | G15: + | H15: 0 | I15: locus_tag=prodigal_1_12;partial=00;start_type=ATG;rbs_motif=AGGAG;rbs_spacer=5-10bp;gc_cont=0.722;conf=100.00;score=127.44;cscore=104.02;sscore=23.42;rscore=15.89;uscore=2.98;tscore=4.54; | S15: =MID($I15,11,12) -> prodigal_1_1 | T15: =MID($I15,11,13) -> prodigal_1_12 | U15: =MID($I15,11,14) -> prodigal_1_12; | V15: =MID($I15,11,15) -> prodigal_1_12;p | W15: =MID($I15,11,16) -> prodigal_1_12;pa | Z15: =MATCH(S15,Description!$A$2:$A$4489,0) -> 1 | AA15: =MATCH(T15,Description!$A$2:$A$4489,0) -> 224 | AB15: =MATCH(U15,Description!$A$2:$A$4489,0) -> #N/A | AC15: =MATCH(V15,Description!$A$2:$A$4489,0) -> #N/A | AD15: 224 | AE15: {=INDEX(Description!A$2:A$4489,Merged!$AD15)} -> prodigal_1_12 | AF15: {=INDEX(Description!B$2:B$4489,Merged!$AD15)} -> P24562 | AG15: {=INDEX(Description!C$2:C$4489,Merged!$AD15)} -> PLPHP_PSEAE | AH15: {=INDEX(Description!D$2:D$4489,Merged!$AD15)} -> Pyridoxal_phosphate_homeostasis_protein | AI15: {=INDEX(Description!E$2:E$4489,Merged!$AD15)} -> yggS | AJ15: =I15&$AJ$2&AF15&$AJ$2&AG15&$AJ$2&AH15&$AJ$2&AI15 -> locus_tag=prodigal_1_12;partial=00;start_type=ATG;rbs_motif=AGGAG;rbs_spacer=5-10bp;gc_cont=0.722;conf=100.00;score=127.44;cscore=104.02;sscore=23.42;rscore=15.89;uscore=2.98;tscore=4.54;;P24562;PLPHP_PSEAE;Pyridoxal_phosphate_homeostasis_protein;yggS
... A4488: X._Sof1_WGS | B4488: Prodigal_v2.6.3 | C4488: gene | D4488: 4911889 | E4488: 4912155 | F4488: 44.2 | G4488: + | H4488: 0 | I4488: locus_tag=prodigal_1_4485;partial=00;start_type=ATG;rbs_motif=AGGA;rbs_spacer=5-10bp;gc_cont=0.685;conf=100.00;score=44.19;cscore=31.58;sscore=12.60;rscore=7.30;uscore=0.76;tscore=4.54; | S4488: =MID($I4488,11,12) -> prodigal_1_4 | T4488: =MID($I4488,11,13) -> prodigal_1_44 | U4488: =MID($I4488,11,14) -> prodigal_1_448 | V4488: =MID($I4488,11,15) -> prodigal_1_4485 | W4488: =MID($I4488,11,16) -> prodigal_1_4485; | Z4488: =MATCH(S4488,Description!$A$2:$A$4489,0) -> 3337 | AA4488: =MATCH(T4488,Description!$A$2:$A$4489,0) -> 3782 | AB4488: =MATCH(U4488,Description!$A$2:$A$4489,0) -> 3871 | AC4488: =MATCH(V4488,Description!$A$2:$A$4489,0) -> 3877 | AD4488: 3877 | AE4488: {=INDEX(Description!A$2:A$4489,Merged!$AD4488)} -> prodigal_1_4485 | AF4488: {=INDEX(Description!B$2:B$4489,Merged!$AD4488)} -> A7IFZ2 | AG4488: {=INDEX(Description!C$2:C$4489,Merged!$AD4488)} -> RS20_XANP2 | AH4488: {=INDEX(Description!D$2:D$4489,Merged!$AD4488)} -> 30S_ribosomal_protein_S20 | AI4488: {=INDEX(Description!E$2:E$4489,Merged!$AD4488)} -> rpsT | AJ4488: =I4488&$AJ$2&AF4488&$AJ$2&AG4488&$AJ$2&AH4488&$AJ$2&AI4488 -> locus_tag=prodigal_1_4485;partial=00;start_type=ATG;rbs_motif=AGGA;rbs_spacer=5-10bp;gc_cont=0.685;conf=100.00;score=44.19;cscore=31.58;sscore=12.60;rscore=7.30;uscore=0.76;tscore=4.54;;A7IFZ2;RS20_XANP2;30S_ribosomal_protein_S20;rpsT

Sheet new_gff
A1: ##gff-version 3
A2: # Sequence Data: seqnum=1;seqlen=4913175;seqhdr=#X._Sof1_WGS Xanthobacter chromosome, complete genome#
A3: # Model Data: version=Prodigal.v2.6.3;run_type=Metagenomic;model=#36|Ralstonia_solanacearum_PSI07|B|66.1|11|1#;gc_cont=66.10;transl_table=11;uses_sd=1
A4: X._Sof1_WGS | B4: Prodigal_v2.6.3 | C4: gene | D4: 1 | E4: 1500 | F4: 272.2 | G4: + | H4: 0 | I4: locus_tag=prodigal_1_1;partial=10;start_type=Edge;rbs_motif=None;rbs_spacer=None;gc_cont=0.684;conf=99.99;score=272.19;cscore=268.97;sscore=3.22;rscore=0.00;uscore=0.00;tscore=3.22;;A7IB67;DNAA_XANP2;Chromosomal_replication_initiator_protein_DnaA;dnaA
A5: X._Sof1_WGS | B5: Prodigal_v2.6.3 | C5: gene | D5: 1906 | E5: 3030 | F5: 250.3 | G5: + | H5: 0 | I5: locus_tag=prodigal_1_2;partial=00;start_type=ATG;rbs_motif=None;rbs_spacer=None;gc_cont=0.675;conf=99.99;score=249.64;cscore=246.11;sscore=3.53;rscore=-3.31;uscore=2.95;tscore=4.54;;B8GXP6;DPO3B_CAUVN;Beta_sliding_clamp;dnaN
A6: X._Sof1_WGS | B6: Prodigal_v2.6.3 | C6: gene | D6: 3170 | E6: 4411 | F6: 190.6 | G6: + | H6: 0 | I6: locus_tag=prodigal_1_3;partial=00;start_type=ATG;rbs_motif=None;rbs_spacer=None;gc_cont=0.721;conf=99.99;score=190.65;cscore=190.21;sscore=0.44;rscore=-3.31;uscore=-0.80;tscore=4.54;;Q98BH1;RECF_RHILO;DNA_replication_and_repair_protein_RecF;recF
A7: X._Sof1_WGS | B7: Prodigal_v2.6.3 | C7: gene | D7: 4601 | E7: 5272 | F7: 119.5 | G7: + | H7: 0 | I7: locus_tag=prodigal_1_4;partial=00;start_type=ATG;rbs_motif=None;rbs_spacer=None;gc_cont=0.683;conf=100.00;score=118.82;cscore=116.01;sscore=2.81;rscore=-3.31;uscore=2.23;tscore=4.54;;P75954;YCFS_ECOLI;Probable_L,D-transpeptidase_YcfS;ycfS
A8: X._Sof1_WGS | B8: Prodigal_v2.6.3 | C8: gene | D8: 5430 | E8: 6959 | F8: 350.6 | G8: + | H8: 0 | I8: locus_tag=prodigal_1_5;partial=00;start_type=ATG;rbs_motif=None;rbs_spacer=None;gc_cont=0.688;conf=99.99;score=350.64;cscore=346.05;sscore=4.59;rscore=-3.31;uscore=3.36;tscore=4.54;;A9MDU4;SYH_BRUC2;Histidine--tRNA_ligase;hisS
A9: X._Sof1_WGS | B9: Prodigal_v2.6.3 | C9: gene | D9: 7202 | E9: 8701 | F9: 354.8 | G9: + | H9: 0 | I9: locus_tag=prodigal_1_6;partial=00;start_type=ATG;rbs_motif=GGAG/GAGG;rbs_spacer=5-10bp;gc_cont=0.651;conf=99.99;score=354.11;cscore=340.10;sscore=14.02;rscore=8.88;uscore=1.24;tscore=4.54;;Q8U2H4;GLMM_PYRFU;Probable_phosphoglucosamine_mutase;glmM
A10: X._Sof1_WGS | B10: Prodigal_v2.6.3 | C10: gene | D10: 9183 | E10: 9347 | F10: 18.7 | G10: + | H10: 0 | I10: locus_tag=prodigal_1_7;partial=00;start_type=ATG;rbs_motif=GGA/GAG/AGG;rbs_spacer=5-10bp;gc_cont=0.648;conf=98.44;score=18.03;cscore=17.77;sscore=0.26;rscore=0.47;uscore=-2.50;tscore=2.94;;*;0;0;0
A11: X._Sof1_WGS | B11: Prodigal_v2.6.3 | C11: gene | D11: 9356 | E11: 9832 | F11: 104 | G11: + | H11: 0 | I11: locus_tag=prodigal_1_8;partial=00;start_type=ATG;rbs_motif=GGAG/GAGG;rbs_spacer=5-10bp;gc_cont=0.683;conf=100.00;score=105.22;cscore=91.36;sscore=13.86;rscore=8.88;uscore=-0.75;tscore=4.54;;*;0;0;0
A12: X._Sof1_WGS | B12: Prodigal_v2.6.3 | C12: gene | D12: 9905 | E12: 11275 | F12: 291.6 | G12: + | H12: 0 | I12: locus_tag=prodigal_1_9;partial=00;start_type=ATG;rbs_motif=AGGAG;rbs_spacer=5-10bp;gc_cont=0.729;conf=99.99;score=291.55;cscore=268.37;sscore=23.18;rscore=15.89;uscore=2.74;tscore=4.54;;A7NG41;AMPA_ROSCS;Probable_cytosol_aminopeptidase;pepA
A13: X._Sof1_WGS | B13: Prodigal_v2.6.3 | C13: gene | D13: 11272 | E13: 12129 | F13: 105.1 | G13: + | H13: 0 | I13: locus_tag=prodigal_1_10;partial=00;start_type=GTG;rbs_motif=None;rbs_spacer=None;gc_cont=0.742;conf=100.00;score=109.73;cscore=115.14;sscore=-5.41;rscore=-3.31;uscore=1.43;tscore=-8.13;;O35010;YKFC_BACSU;Gamma-D-glutamyl-L-lysine_dipeptidyl-peptidase;ykfC
A14: X._Sof1_WGS | B14: Prodigal_v2.6.3 | C14: gene | D14: 12157 | E14: 13788 | F14: 277.8 | G14: - | H14: 0 | I14: locus_tag=prodigal_1_11;partial=00;start_type=ATG;rbs_motif=AGGAG/GGAGG;rbs_spacer=11-12bp;gc_cont=0.691;conf=99.99;score=277.15;cscore=273.13;sscore=4.02;rscore=0.66;uscore=-0.53;tscore=4.54;;Q55434;PHY2_SYNY3;Phytochrome-like_protein_cph2;cph2
A15: X._Sof1_WGS | B15: Prodigal_v2.6.3 | C15: gene | D15: 13906 | E15: 14613 | F15: 127.4 | G15: + | H15: 0 | I15: locus_tag=prodigal_1_12;partial=00;start_type=ATG;rbs_motif=AGGAG;rbs_spacer=5-10bp;gc_cont=0.722;conf=100.00;score=127.44;cscore=104.02;sscore=23.42;rscore=15.89;uscore=2.98;tscore=4.54;;P24562;PLPHP_PSEAE;Pyridoxal_phosphate_homeostasis_protein;yggS
... A4488: X._Sof1_WGS | B4488: Prodigal_v2.6.3 | C4488: gene | D4488: 4911889 | E4488: 4912155 | F4488: 44.2 | G4488: + | H4488: 0 | I4488: locus_tag=prodigal_1_4485;partial=00;start_type=ATG;rbs_motif=AGGA;rbs_spacer=5-10bp;gc_cont=0.685;conf=100.00;score=44.19;cscore=31.58;sscore=12.60;rscore=7.30;uscore=0.76;tscore=4.54;;A7IFZ2;RS20_XANP2;30S_ribosomal_protein_S20;rpsT

Sheet Description
A1: locus_tag | B1: shortName | C1: longName | D1: product | E1: gene
A2: prodigal_1_1 | B2: A7IB67 | C2: DNAA_XANP2 | D2: Chromosomal_replication_initiator_protein_DnaA | E2: dnaA | F2: =COUNTBLANK(C2:C4489) -> 1689
A3: prodigal_1_10 | B3: O35010 | C3: YKFC_BACSU | D3: Gamma-D-glutamyl-L-lysine_dipeptidyl-peptidase | E3: ykfC | F3: 4489
A4: prodigal_1_100 | B4: *
A5: prodigal_1_1000 | B5: P55561 | C5: Y4MB_SINFN | D5: Uncharacterized_outer-membrane_protein_y4mB | E5: yeiF
A6: prodigal_1_1001 | B6: *
A7: prodigal_1_1002 | B7: A9WC34 | C7: MCH_CHLAA | D7: Beta-methylmalyl-CoA_dehydratase | E7: mch
A8: prodigal_1_1003 | B8: *
A9: prodigal_1_1004 | B9: *
A10: prodigal_1_1005 | B10: Q8G9F9 | C10: INHA_PSEPU | D10: Isonitrile_hydratase | E10: inhA
A11: prodigal_1_1006 | B11: B9KNB6 | C11: MCTE_CERSK | D11: (3S)-malyl-CoA_thioesterase | E11: mcl2
A12: prodigal_1_1007 | B12: *
A13: prodigal_1_1008 | B13: A7IGS7 | C13: ATPF1_XANP2 | D13: ATP_synthase_subunit_b_1 | E13: atpF1
A14: prodigal_1_1009 | B14: A7IGS8 | C14: ATPF2_XANP2 | D14: ATP_synthase_subunit_b_2 | E14: atpF2
A15: prodigal_1_101 | B15: Q89S70 | C15: SYGA_BRADU | D15: Glycine--tRNA_ligase_alpha_subunit | E15: glyQ
A16: prodigal_1_1010 | B16: A4WNY7 | C16: ATPL_CERS5 | D16: ATP_synthase_subunit_c | E16: atpE
A17: prodigal_1_1011 | B17: A7IGT0 | C17: ATP6_XANP2 | D17: ATP_synthase_subunit_a | E17: atpB
A18: prodigal_1_1012 | B18: *
A19: prodigal_1_1013 | B19: Q6N1B7 | C19: SMC_RHOPA | D19: Chromosome_partition_protein_Smc | E19: smc
A20: prodigal_1_1014 | B20: Q9CM49 | C20: THIO_PASMU | D20: Thioredoxin | E20: trxA
A21: prodigal_1_1015 | B21: A9B5N1 | C21: LON1_HERA2 | D21: Lon_protease_1 | E21: lon1
A22: prodigal_1_1016 | B22: P63534 | C22: AOFH_MYCBO | D22: Putative_flavin-containing_monoamine_oxidase_AofH | E22: aofH
A23: prodigal_1_1017 | B23: A7ICB3 | C23: RLMN_XANP2 | D23: Dual-specificity_RNA_methyltransferase_RlmN | E23: rlmN
A24: prodigal_1_1018 | B24: *
A25: prodigal_1_1019 | B25: *
A26: prodigal_1_102 | B26: Q3J1R2 | C26: TAKP_CERS4 | D26: Alpha-keto_acid-binding_periplasmic_protein_TakP | E26: takP
A27: prodigal_1_1020 | B27: *
A28: prodigal_1_1021 | B28: A7ICA9 | C28: HIS8_XANP2 | D28: Histidinol-phosphate_aminotransferase | E28: hisC
A29: prodigal_1_1022 | B29: Q04983 | C29: TYRC_ZYMMO | D29: Cyclohexadienyl_dehydrogenase | E29: tyrC
A30: prodigal_1_1023 | B30: Q9Z3S0 | C30: EDD_RHIME | D30: Phosphogluconate_dehydratase | E30: edd
A31: prodigal_1_1024 | B31: *
A32: prodigal_1_1025 | B32: P23545 | C32: PHOR_BACSU | D32: Alkaline_phosphatase_synthesis_sensor_protein_PhoR | E32: phoR
A33: prodigal_1_1026 | B33: Q9CNJ4 | C33: PSTS_PASMU | D33: Phosphate-binding_protein_PstS | E33: pstS
A34: prodigal_1_1027 | B34: Q98FL3 | C34: PSTC_RHILO | D34: Phosphate_transport_system_permease_protein_PstC | E34: pstC
A35: prodigal_1_1028 | B35: Q9CNJ6 | C35: PSTA_PASMU | D35: Phosphate_transport_system_permease_protein_PstA | E35: pstA
A36: prodigal_1_1029 | B36: Q0BTP1 | C36: PSTB_GRABC | D36: Phosphate_import_ATP-binding_protein_PstB | E36: pstB
A37: prodigal_1_103 | B37: Q8ZNN5 | C37: APBC_SALTY | D37: Iron-sulfur_cluster_carrier_protein | E37: apbC
A38: prodigal_1_1030 | B38: Q52989 | C38: PHOU_RHIME | D38: Phosphate-specific_transport_system_accessory_protein_PhoU_homolog | E38: phoU
A39: prodigal_1_1031 | B39: Q52990 | C39: PHOB_RHIME | D39: Phosphate_regulon_transcriptional_regulatory_protein_PhoB | E39: phoB
A40: prodigal_1_1032 | B40: *
...
